Workbook

Sheet Sheet1
A1: Alloy | B1: Etutetic | C1: %Co | D1: %Cr | E1: %Fe | F1: %Ni | G1: Etutetic
A2: Al0.1CoCr3Fe5Ni | C2: 9.9009901 | D2: 29.70297 | E2: 49.50495 | F2: 9.9009901 | G2: -1
A3: Al0.2CoCr3Fe5Ni | C3: 9.8039216 | D3: 29.411765 | E3: 49.019608 | F3: 9.8039216 | G3: -1
A4: Al2.4Co24.4Cr24.4Fe24.4Ni24.4 | C4: 24.4 | D4: 24.4 | E4: 24.4 | F4: 24.4 | G4: -1
A5: Al0.1CoCrFeNi | C5: 24.390244 | D5: 24.390244 | E5: 24.390244 | F5: 24.390244 | G5: -1
A6: Al0.1CoFeNiCr0.9 | C6: 25 | D6: 22.5 | E6: 25 | F6: 25 | G6: -1
A7: Al0.3CoCr3Fe5Ni | C7: 9.7087379 | D7: 29.126214 | E7: 48.543689 | F7: 9.7087379 | G7: -1
A8: Al0.2CoCrFeNi | C8: 23.809524 | D8: 23.809524 | E8: 23.809524 | F8: 23.809524 | G8: -1
A9: Al0.2CoFeNiCr0.8 | C9: 25 | D9: 20 | E9: 25 | F9: 25 | G9: -1
A10: Al0.3CoCr2FeNi | C10: 18.867925 | D10: 37.735849 | E10: 18.867925 | F10: 18.867925 | G10: -1
A11: Al0.25CoCrFeNi | C11: 23.529412 | D11: 23.529412 | E11: 23.529412 | F11: 23.529412 | G11: -1
A12: Al0.3CoCrFeNi | C12: 23.529412 | D12: 23.529412 | E12: 23.529412 | F12: 23.529412 | G12: -1
A13: Al7.0536Cr9.5224Fe15.749Co32.895Ni34.78 | C13: 23.255814 | D13: 23.255814 | E13: 23.255814 | F13: 23.255814 | G13: -1
... A190: Al15.1Cr20.3Fe6.9Co28.2Ni29.5 | C190: 20.8 | D190: 16.3 | E190: 21.8 | F190: 26.3 | G190: -1
A191: Al15.125Cr20.286Fe6.8925Co28.225Ni29.472 | B191: 1 | C191: 21.276596 | D191: 21.276596 | E191: 21.276596 | F191: 21.276596 | G191: 1
A192: Al15.2Cr19.9Fe17.4Co23.2Ni24.3 | C192: 16.2 | D192: 19.1 | E192: 32.5 | F192: 17.3 | G192: -1
A193: Al15.247Cr19.915Fe17.397Co23.157Ni24.284 | C193: 21.738 | D193: 19.271 | E193: 20.641 | F193: 23.443 | G193: -1
A194: Al15.3Cr20.4Fe7.7Co27.4Ni29.2 | C194: 21.7 | D194: 19.3 | E194: 20.6 | F194: 23.4 | G194: -1
A195: Al15.327Cr20.411Fe7.7228Co27.382Ni29.157 | C195: 25 | D195: 10 | E195: 25 | F195: 25 | G195: -1
A196: Al15.379Cr20.469Fe9.0169Co26.904Ni28.231 | C196: 28.2 | D196: 20.3 | E196: 6.9 | F196: 29.5 | G196: -1
A197: AlCoCrFeNi2.5 | C197: 28.225 | D197: 20.286 | E197: 6.8925 | F197: 29.472 | G197: -1
A198: Al15.4Cr20.5Fe9Co26.9Ni28.2 | C198: 23.2 | D198: 19.9 | E198: 17.4 | F198: 24.3 | G198: -1
A199: Al15.6Cr20.4Fe12.6Co25Ni26.4 | C199: 23.157 | D199: 19.915 | E199: 17.397 | F199: 24.284 | G199: -1
A200: Al0.74NiCoFeCr | C200: 27.4 | D200: 20.4 | E200: 7.7 | F200: 29.2 | G200: -1
A201: Al15.63Ni21.09Co21.09Fe21.09Cr21.09 | C201: 27.382 | D201: 20.411 | E201: 7.7228 | F201: 29.157 | G201: -1
A202: Al15.635Cr20.423Fe12.565Co24.963Ni26.415 | C202: 26.904 | D202: 20.469 | E202: 9.0169 | F202: 28.231 | G202: -1
A203: Al15.7Cr20.5Fe10.5Co25.8Ni27.5 | C203: 15.384615 | D203: 15.384615 | E203: 15.384615 | F203: 38.461538 | G203: -1
... A222: Al16.6Cr16.4Fe21.7Co20Ni25.3 | C222: 16.7 | D222: 19.7 | E222: 26.4 | F222: 21.1 | G222: -1
A223: Al16.605Cr17.798Fe23.996Co18.329Ni23.271 | B223: 1 | C223: 16.129032 | D223: 16.129032 | E223: 16.129032 | F223: 35.483871 | G223: 1
A224: Al16.6Co20.8Cr20.8Fe20.8Ni20.8 | C224: 16.721 | D224: 19.712 | E224: 26.373 | F224: 21.064 | G224: -1
A225: AlCo0.2CrFeNi2.8 | B225: 1 | C225: 16.393443 | D225: 16.393443 | E225: 16.393443 | F225: 34.42623 | G225: 1
A226: AlCo0.4CrFeNi2.6 | C226: 14.6 | D226: 21.4 | E226: 31.8 | F226: 15.7 | G226: -1
A227: AlCo0.6CrFeNi2.4 | C227: 14.633 | D227: 21.37 | E227: 31.821 | F227: 15.659 | G227: -1
A228: AlCo0.8CrFeNi2.2 | C228: 20.035 | D228: 16.43 | E228: 21.664 | F228: 25.28 | G228: -1
A229: AlCoCrFeNi2 | C229: 18.3 | D229: 17.8 | E229: 24 | F229: 23.3 | G229: -1
A230: AlCoCr2FeNi | C230: 20 | D230: 16.4 | E230: 21.7 | F230: 25.3 | G230: -1
A231: Al0.8CoCrFeNi | C231: 18.329 | D231: 17.798 | E231: 23.996 | F231: 23.271 | G231: -1
A232: Al16.7Cr22.8Fe31.1Co12.9Ni16.5 | C232: 20.8 | D232: 20.8 | E232: 20.8 | F232: 20.8 | G232: -1
A233: Al16.7Cr13.3Fe17.4Co23.3Ni29.3 | B233: 1 | C233: 3.3333333 | D233: 16.666667 | E233: 16.666667 | F233: 46.666667 | G233: 1
A234: Al16.7Cr11.8Fe15.4Co24.7Ni31.3 | B234: 1 | C234: 6.6666667 | D234: 16.666667 | E234: 16.666667 | F234: 43.333333 | G234: 1
...

Sheet Sheet2
A1: Alloy | B1: VEC
A2: Al0.1CoCr3Fe5Ni | B2: 7.6535
A3: Al0.2CoCr3Fe5Ni | B3: 7.6078
A4: Al2.4Co24.4Cr24.4Fe24.4Ni24.4 | B4: 8.124
A5: Al0.1CoCrFeNi | B5: 8.122
A6: Al0.1CoFeNiCr0.9 | B6: 8.175
A7: Al0.3CoCr3Fe5Ni | B7: 7.5631
A8: Al0.2CoCrFeNi | B8: 8
A9: Al0.2CoFeNiCr0.8 | B9: 8.1
A10: Al0.3CoCr2FeNi | B10: 7.5283
A11: Al0.25CoCrFeNi | B11: 7.9412
A12: Al0.25CoCrFeNi | B12: 7.9412
A13: Al0.3CoCrFeNi | B13: 7.8837
... A673: Al48.8Cr13.3Fe17.5Co9Ni11.3 | B673: 5.6076

Sheet Sheet4
A1: Alloy | B1: Eutectic | C1: Actual phase
A2: Al0.1CoCr3Fe5Ni | B2: -1
A3: Al0.2CoCr3Fe5Ni | B3: -1
A4: Al2.4Co24.4Cr24.4Fe24.4Ni24.4 | B4: 0 | C4: FCC
A5: Al0.1CoCrFeNi | B5: 0 | C5: FCC
A6: Al0.1CoFeNiCr0.9 | B6: -1
A7: Al0.3CoCr3Fe5Ni | B7: -1
A8: Al0.2CoCrFeNi | B8: 1 | C8: BCC1+B2(ordered BCC)
A9: Al0.2CoFeNiCr0.8 | B9: -1
A10: Al0.3CoCr2FeNi | B10: -1
A11: Al0.25CoCrFeNi | B11: 0 | C11: FCC
A12: Al0.25CoCrFeNi | B12: 0 | C12: FCC
A13: Al0.3CoCrFeNi | B13: -1 | C13: IM
A14: Al7.0536Cr9.5224Fe15.749Co32.895Ni34.78 | B14: -1
A15: Al7.1Cr9.5Fe15.7Co32.9Ni34.8 | B15: -1
A16: Al7.2Co23.2Cr23.2Fe23.2Ni23.2 | B16: -1 | C16: IM
A17: Al7.2069Cr9.6072Fe12.998Co34.049Ni36.138 | B17: -1
A18: Al7.2Cr9.6Fe13Co34Ni36.1 | B18: -1
A19: Al0.3CoFeNiCr0.7 | B19: -1
A20: Al7.6571Cr9.5984Fe26.587Co27.261Ni28.897 | B20: -1
A21: Al7.6864Cr9.7668Fe18.702Co31.106Ni32.739 | B21: -1
A22: Al7.7Cr9.6Fe26.6Co27.3Ni28.9 | B22: -1
A23: Al7.7Cr9.8Fe18.7Co31.1Ni32.7 | B23: -1
A24: Al7.7981Cr9.8581Fe22.204Co29.129Ni31.011 | B24: -1
A25: Al7.8Cr9.9Fe22.2Co29.1Ni31 | B25: -1
A26: Al7.9Cr10.1Fe37.3Co21.5Ni23.2 | B26: -1
A27: Al7.9214Cr10.128Fe37.308Co21.456Ni23.187 | B27: -1
A28: Al8.2Cr11.1Fe9.5Co34.7Ni36.5 | B28: -1
... A33: Al8.4353Cr11.298Fe16.225Co31.074Ni32.968 | B33: -1
A34: Al0.375CoCrFeNi | B34: 0 | C34: FCC
A35: Al0.375CoCrFeNi | B35: 0 | C35: FCC
A36: CoCrFeNiAl0.38 | B36: -1
A37: Al8.6895Cr10.442Fe32.126Co23.472Ni25.271 | B37: -1
A38: Al8.7Cr10.4Fe32.1Co23.5Ni25.3 | B38: -1
A39: Al8.7Cr10.9Fe27.2Co25.7Ni27.5 | B39: -1
A40: Al8.7167Cr10.894Fe27.204Co25.722Ni27.464 | B40: -1
A41: Al8.7665Cr11.071Fe13.554Co32.427Ni34.182 | B41: -1
A42: Al8.7869Cr11.363Fe19.584Co29.085Ni31.181 | B42: -1
A43: Al8.8Cr11.4Fe19.6Co29.1Ni31.2 | B43: -1
A44: Al8.8Cr11.1Fe13.6Co32.4Ni34.2 | B44: -1
...

Sheet Sheet7
A1: {=IF(ROW()<=COUNTA(Sheet1!A:A), INDEX(Sheet1!A:A, ROW()), INDEX(Sheet4!A:A, ROW()-COUNTA(Sheet1!A:A)))} -> Alloy | B1: Actual Phase | C1: Eutectic (from phases) | D1: VEC | E1: Eutetic (By self) | F1: Eutetic (final) | G1: %Co | H1: %Cr | I1: %Fe | J1: %Ni
A2: {=IF(ROW()<=COUNTA(Sheet1!A:A), INDEX(Sheet1!A:A, ROW()), INDEX(Sheet4!A:A, ROW()-COUNTA(Sheet1!A:A)))} -> Al0.1CoCr3Fe5Ni | B2: =_xlfn.XLOOKUP(A2, Sheet4!A:A, Sheet4!C:C) -> 0 | C2: -1 | D2: =_xlfn.XLOOKUP(A2, Sheet2!A:A, Sheet2!B:B) -> 7.6535 | E2: =_xlfn.XLOOKUP(A2, Sheet1!A:A, Sheet1!G:G) -> -1 | F2: =IF(OR(C2=1, E2=1), 1, IF(OR(C2=0, E2=0), 0, -1)) -> -1 | G2: {=_xlfn.XLOOKUP(A2, Sheet1!A:A, Sheet1!C:F)} -> 9.9009901 | H2: 29.70297 | I2: 49.50495 | J2: 9.9009901
A3: {=IF(ROW()<=COUNTA(Sheet1!A:A), INDEX(Sheet1!A:A, ROW()), INDEX(Sheet4!A:A, ROW()-COUNTA(Sheet1!A:A)))} -> Al0.2CoCr3Fe5Ni | B3: =_xlfn.XLOOKUP(A3, Sheet4!A:A, Sheet4!C:C) -> 0 | C3: -1 | D3: =_xlfn.XLOOKUP(A3, Sheet2!A:A, Sheet2!B:B) -> 7.6078 | E3: =_xlfn.XLOOKUP(A3, Sheet1!A:A, Sheet1!G:G) -> -1 | F3: =IF(OR(C3=1, E3=1), 1, IF(OR(C3=0, E3=0), 0, -1)) -> -1 | G3: {=_xlfn.XLOOKUP(A3, Sheet1!A:A, Sheet1!C:F)} -> 9.8039216 | H3: 29.411765 | I3: 49.019608 | J3: 9.8039216
A4: {=IF(ROW()<=COUNTA(Sheet1!A:A), INDEX(Sheet1!A:A, ROW()), INDEX(Sheet4!A:A, ROW()-COUNTA(Sheet1!A:A)))} -> Al2.4Co24.4Cr24.4Fe24.4Ni24.4 | B4: =_xlfn.XLOOKUP(A4, Sheet4!A:A, Sheet4!C:C) -> FCC | C4: 0 | D4: =_xlfn.XLOOKUP(A4, Sheet2!A:A, Sheet2!B:B) -> 8.124 | E4: =_xlfn.XLOOKUP(A4, Sheet1!A:A, Sheet1!G:G) -> -1 | F4: =IF(OR(C4=1, E4=1), 1, IF(OR(C4=0, E4=0), 0, -1)) -> 0 | G4: {=_xlfn.XLOOKUP(A4, Sheet1!A:A, Sheet1!C:F)} -> 24.4 | H4: 24.4 | I4: 24.4 | J4: 24.4
A5: {=IF(ROW()<=COUNTA(Sheet1!A:A), INDEX(Sheet1!A:A, ROW()), INDEX(Sheet4!A:A, ROW()-COUNTA(Sheet1!A:A)))} -> Al0.1CoCrFeNi | B5: =_xlfn.XLOOKUP(A5, Sheet4!A:A, Sheet4!C:C) -> FCC | C5: 0 | D5: =_xlfn.XLOOKUP(A5, Sheet2!A:A, Sheet2!B:B) -> 8.122 | E5: =_xlfn.XLOOKUP(A5, Sheet1!A:A, Sheet1!G:G) -> -1 | F5: =IF(OR(C5=1, E5=1), 1, IF(OR(C5=0, E5=0), 0, -1)) -> 0 | G5: {=_xlfn.XLOOKUP(A5, Sheet1!A:A, Sheet1!C:F)} -> 24.390244 | H5: 24.390244 | I5: 24.390244 | J5: 24.390244
A6: {=IF(ROW()<=COUNTA(Sheet1!A:A), INDEX(Sheet1!A:A, ROW()), INDEX(Sheet4!A:A, ROW()-COUNTA(Sheet1!A:A)))} -> Al0.1CoFeNiCr0.9 | B6: =_xlfn.XLOOKUP(A6, Sheet4!A:A, Sheet4!C:C) -> 0 | C6: -1 | D6: =_xlfn.XLOOKUP(A6, Sheet2!A:A, Sheet2!B:B) -> 8.175 | E6: =_xlfn.XLOOKUP(A6, Sheet1!A:A, Sheet1!G:G) -> -1 | F6: =IF(OR(C6=1, E6=1), 1, IF(OR(C6=0, E6=0), 0, -1)) -> -1 | G6: {=_xlfn.XLOOKUP(A6, Sheet1!A:A, Sheet1!C:F)} -> 25 | H6: 22.5 | I6: 25 | J6: 25
A7: {=IF(ROW()<=COUNTA(Sheet1!A:A), INDEX(Sheet1!A:A, ROW()), INDEX(Sheet4!A:A, ROW()-COUNTA(Sheet1!A:A)))} -> Al0.3CoCr3Fe5Ni | B7: =_xlfn.XLOOKUP(A7, Sheet4!A:A, Sheet4!C:C) -> 0 | C7: -1 | D7: =_xlfn.XLOOKUP(A7, Sheet2!A:A, Sheet2!B:B) -> 7.5631 | E7: =_xlfn.XLOOKUP(A7, Sheet1!A:A, Sheet1!G:G) -> -1 | F7: =IF(OR(C7=1, E7=1), 1, IF(OR(C7=0, E7=0), 0, -1)) -> -1 | G7: {=_xlfn.XLOOKUP(A7, Sheet1!A:A, Sheet1!C:F)} -> 9.7087379 | H7: 29.126214 | I7: 48.543689 | J7: 9.7087379
A8: {=IF(ROW()<=COUNTA(Sheet1!A:A), INDEX(Sheet1!A:A, ROW()), INDEX(Sheet4!A:A, ROW()-COUNTA(Sheet1!A:A)))} -> Al0.2CoCrFeNi | B8: =_xlfn.XLOOKUP(A8, Sheet4!A:A, Sheet4!C:C) -> BCC1+B2(ordered BCC) | C8: 1 | D8: =_xlfn.XLOOKUP(A8, Sheet2!A:A, Sheet2!B:B) -> 8 | E8: =_xlfn.XLOOKUP(A8, Sheet1!A:A, Sheet1!G:G) -> -1 | F8: =IF(OR(C8=1, E8=1), 1, IF(OR(C8=0, E8=0), 0, -1)) -> 1 | G8: {=_xlfn.XLOOKUP(A8, Sheet1!A:A, Sheet1!C:F)} -> 23.809524 | H8: 23.809524 | I8: 23.809524 | J8: 23.809524
A9: {=IF(ROW()<=COUNTA(Sheet1!A:A), INDEX(Sheet1!A:A, ROW()), INDEX(Sheet4!A:A, ROW()-COUNTA(Sheet1!A:A)))} -> Al0.2CoFeNiCr0.8 | B9: =_xlfn.XLOOKUP(A9, Sheet4!A:A, Sheet4!C:C) -> 0 | C9: -1 | D9: =_xlfn.XLOOKUP(A9, Sheet2!A:A, Sheet2!B:B) -> 8.1 | E9: =_xlfn.XLOOKUP(A9, Sheet1!A:A, Sheet1!G:G) -> -1 | F9: =IF(OR(C9=1, E9=1), 1, IF(OR(C9=0, E9=0), 0, -1)) -> -1 | G9: {=_xlfn.XLOOKUP(A9, Sheet1!A:A, Sheet1!C:F)} -> 25 | H9: 20 | I9: 25 | J9: 25
A10: {=IF(ROW()<=COUNTA(Sheet1!A:A), INDEX(Sheet1!A:A, ROW()), INDEX(Sheet4!A:A, ROW()-COUNTA(Sheet1!A:A)))} -> Al0.3CoCr2FeNi | B10: =_xlfn.XLOOKUP(A10, Sheet4!A:A, Sheet4!C:C) -> 0 | C10: -1 | D10: =_xlfn.XLOOKUP(A10, Sheet2!A:A, Sheet2!B:B) -> 7.5283 | E10: =_xlfn.XLOOKUP(A10, Sheet1!A:A, Sheet1!G:G) -> -1 | F10: =IF(OR(C10=1, E10=1), 1, IF(OR(C10=0, E10=0), 0, -1)) -> -1 | G10: {=_xlfn.XLOOKUP(A10, Sheet1!A:A, Sheet1!C:F)} -> 18.867925 | H10: 37.735849 | I10: 18.867925 | J10: 18.867925
A11: {=IF(ROW()<=COUNTA(Sheet1!A:A), INDEX(Sheet1!A:A, ROW()), INDEX(Sheet4!A:A, ROW()-COUNTA(Sheet1!A:A)))} -> Al0.25CoCrFeNi | B11: =_xlfn.XLOOKUP(A11, Sheet4!A:A, Sheet4!C:C) -> FCC | C11: 0 | D11: =_xlfn.XLOOKUP(A11, Sheet2!A:A, Sheet2!B:B) -> 7.9412 | E11: =_xlfn.XLOOKUP(A11, Sheet1!A:A, Sheet1!G:G) -> -1 | F11: =IF(OR(C11=1, E11=1), 1, IF(OR(C11=0, E11=0), 0, -1)) -> 0 | G11: {=_xlfn.XLOOKUP(A11, Sheet1!A:A, Sheet1!C:F)} -> 23.529412 | H11: 23.529412 | I11: 23.529412 | J11: 23.529412
A12: {=IF(ROW()<=COUNTA(Sheet1!A:A), INDEX(Sheet1!A:A, ROW()), INDEX(Sheet4!A:A, ROW()-COUNTA(Sheet1!A:A)))} -> Al0.3CoCrFeNi | B12: =_xlfn.XLOOKUP(A12, Sheet4!A:A, Sheet4!C:C) -> IM | C12: -1 | D12: =_xlfn.XLOOKUP(A12, Sheet2!A:A, Sheet2!B:B) -> 7.8837 | E12: =_xlfn.XLOOKUP(A12, Sheet1!A:A, Sheet1!G:G) -> -1 | F12: =IF(OR(C12=1, E12=1), 1, IF(OR(C12=0, E12=0), 0, -1)) -> -1 | G12: {=_xlfn.XLOOKUP(A12, Sheet1!A:A, Sheet1!C:F)} -> 23.529412 | H12: 23.529412 | I12: 23.529412 | J12: 23.529412
A13: {=IF(ROW()<=COUNTA(Sheet1!A:A), INDEX(Sheet1!A:A, ROW()), INDEX(Sheet4!A:A, ROW()-COUNTA(Sheet1!A:A)))} -> Al7.0536Cr9.5224Fe15.749Co32.895Ni34.78 | B13: =_xlfn.XLOOKUP(A13, Sheet4!A:A, Sheet4!C:C) -> 0 | C13: -1 | D13: =_xlfn.XLOOKUP(A13, Sheet2!A:A, Sheet2!B:B) -> 8.4814 | E13: =_xlfn.XLOOKUP(A13, Sheet1!A:A, Sheet1!G:G) -> -1 | F13: =IF(OR(C13=1, E13=1), 1, IF(OR(C13=0, E13=0), 0, -1)) -> -1 | G13: {=_xlfn.XLOOKUP(A13, Sheet1!A:A, Sheet1!C:F)} -> 23.255814 | H13: 23.255814 | I13: 23.255814 | J13: 23.255814
... A750: {=IF(ROW()<=COUNTA(Sheet1!A:A), INDEX(Sheet1!A:A, ROW()), INDEX(Sheet4!A:A, ROW()-COUNTA(Sheet1!A:A)))} -> Al0.278 Co0.556 Cr0.556 Cu0.556 Fe0.556 Ni0.556 Ti1 | B750: =_xlfn.XLOOKUP(A750, Sheet4!A:A, Sheet4!C:C) -> #N/A | C750: -1 | D750: =_xlfn.XLOOKUP(A750, Sheet2!A:A, Sheet2!B:B) -> #N/A | E750: =_xlfn.XLOOKUP(A750, Sheet1!A:A, Sheet1!G:G) -> 1 | F750: =IF(OR(C750=1, E750=1), 1, IF(OR(C750=0, E750=0), 0, -1)) -> 1 | G750: {=_xlfn.XLOOKUP(A750, Sheet1!A:A, Sheet1!C:F)} -> 0 | H750: 0 | I750: 0 | J750: 0
A751: {=IF(ROW()<=COUNTA(Sheet1!A:A), INDEX(Sheet1!A:A, ROW()), INDEX(Sheet4!A:A, ROW()-COUNTA(Sheet1!A:A)))} -> Alloy | B751: =_xlfn.XLOOKUP(A751, Sheet4!A:A, Sheet4!C:C) -> Actual phase | C751: -1 | D751: =_xlfn.XLOOKUP(A751, Sheet2!A:A, Sheet2!B:B) -> VEC | E751: =_xlfn.XLOOKUP(A751, Sheet1!A:A, Sheet1!G:G) -> Etutetic | F751: =IF(OR(C751=1, E751=1), 1, IF(OR(C751=0, E751=0), 0, -1)) -> -1 | G751: {=_xlfn.XLOOKUP(A751, Sheet1!A:A, Sheet1!C:F)} -> %Co | H751: %Cr | I751: %Fe | J751: %Ni
A752: {=IF(ROW()<=COUNTA(Sheet1!A:A), INDEX(Sheet1!A:A, ROW()), INDEX(Sheet4!A:A, ROW()-COUNTA(Sheet1!A:A)))} -> Al0.1CoCr3Fe5Ni | B752: =_xlfn.XLOOKUP(A752, Sheet4!A:A, Sheet4!C:C) -> 0 | C752: -1 | D752: =_xlfn.XLOOKUP(A752, Sheet2!A:A, Sheet2!B:B) -> 7.6535 | E752: =_xlfn.XLOOKUP(A752, Sheet1!A:A, Sheet1!G:G) -> -1 | F752: =IF(OR(C752=1, E752=1), 1, IF(OR(C752=0, E752=0), 0, -1)) -> -1 | G752: {=_xlfn.XLOOKUP(A752, Sheet1!A:A, Sheet1!C:F)} -> 9.9009901 | H752: 29.70297 | I752: 49.50495 | J752: 9.9009901
A753: {=IF(ROW()<=COUNTA(Sheet1!A:A), INDEX(Sheet1!A:A, ROW()), INDEX(Sheet4!A:A, ROW()-COUNTA(Sheet1!A:A)))} -> Al0.2CoCr3Fe5Ni | B753: =_xlfn.XLOOKUP(A753, Sheet4!A:A, Sheet4!C:C) -> 0 | C753: -1 | D753: =_xlfn.XLOOKUP(A753, Sheet2!A:A, Sheet2!B:B) -> 7.6078 | E753: =_xlfn.XLOOKUP(A753, Sheet1!A:A, Sheet1!G:G) -> -1 | F753: =IF(OR(C753=1, E753=1), 1, IF(OR(C753=0, E753=0), 0, -1)) -> -1 | G753: {=_xlfn.XLOOKUP(A753, Sheet1!A:A, Sheet1!C:F)} -> 9.8039216 | H753: 29.411765 | I753: 49.019608 | J753: 9.8039216
A754: {=IF(ROW()<=COUNTA(Sheet1!A:A), INDEX(Sheet1!A:A, ROW()), INDEX(Sheet4!A:A, ROW()-COUNTA(Sheet1!A:A)))} -> Al2.4Co24.4Cr24.4Fe24.4Ni24.4 | B754: =_xlfn.XLOOKUP(A754, Sheet4!A:A, Sheet4!C:C) -> FCC | C754: 0 | D754: =_xlfn.XLOOKUP(A754, Sheet2!A:A, Sheet2!B:B) -> 8.124 | E754: =_xlfn.XLOOKUP(A754, Sheet1!A:A, Sheet1!G:G) -> -1 | F754: =IF(OR(C754=1, E754=1), 1, IF(OR(C754=0, E754=0), 0, -1)) -> 0 | G754: {=_xlfn.XLOOKUP(A754, Sheet1!A:A, Sheet1!C:F)} -> 24.4 | H754: 24.4 | I754: 24.4 | J754: 24.4
A755: {=IF(ROW()<=COUNTA(Sheet1!A:A), INDEX(Sheet1!A:A, ROW()), INDEX(Sheet4!A:A, ROW()-COUNTA(Sheet1!A:A)))} -> Al0.1CoCrFeNi | B755: =_xlfn.XLOOKUP(A755, Sheet4!A:A, Sheet4!C:C) -> FCC | C755: 0 | D755: =_xlfn.XLOOKUP(A755, Sheet2!A:A, Sheet2!B:B) -> 8.122 | E755: =_xlfn.XLOOKUP(A755, Sheet1!A:A, Sheet1!G:G) -> -1 | F755: =IF(OR(C755=1, E755=1), 1, IF(OR(C755=0, E755=0), 0, -1)) -> 0 | G755: {=_xlfn.XLOOKUP(A755, Sheet1!A:A, Sheet1!C:F)} -> 24.390244 | H755: 24.390244 | I755: 24.390244 | J755: 24.390244
A756: {=IF(ROW()<=COUNTA(Sheet1!A:A), INDEX(Sheet1!A:A, ROW()), INDEX(Sheet4!A:A, ROW()-COUNTA(Sheet1!A:A)))} -> Al0.1CoFeNiCr0.9 | B756: =_xlfn.XLOOKUP(A756, Sheet4!A:A, Sheet4!C:C) -> 0 | C756: -1 | D756: =_xlfn.XLOOKUP(A756, Sheet2!A:A, Sheet2!B:B) -> 8.175 | E756: =_xlfn.XLOOKUP(A756, Sheet1!A:A, Sheet1!G:G) -> -1 | F756: =IF(OR(C756=1, E756=1), 1, IF(OR(C756=0, E756=0), 0, -1)) -> -1 | G756: {=_xlfn.XLOOKUP(A756, Sheet1!A:A, Sheet1!C:F)} -> 25 | H756: 22.5 | I756: 25 | J756: 25
A757: {=IF(ROW()<=COUNTA(Sheet1!A:A), INDEX(Sheet1!A:A, ROW()), INDEX(Sheet4!A:A, ROW()-COUNTA(Sheet1!A:A)))} -> Al0.3CoCr3Fe5Ni | B757: =_xlfn.XLOOKUP(A757, Sheet4!A:A, Sheet4!C:C) -> 0 | C757: -1 | D757: =_xlfn.XLOOKUP(A757, Sheet2!A:A, Sheet2!B:B) -> 7.5631 | E757: =_xlfn.XLOOKUP(A757, Sheet1!A:A, Sheet1!G:G) -> -1 | F757: =IF(OR(C757=1, E757=1), 1, IF(OR(C757=0, E757=0), 0, -1)) -> -1 | G757: {=_xlfn.XLOOKUP(A757, Sheet1!A:A, Sheet1!C:F)} -> 9.7087379 | H757: 29.126214 | I757: 48.543689 | J757: 9.7087379
A758: {=IF(ROW()<=COUNTA(Sheet1!A:A), INDEX(Sheet1!A:A, ROW()), INDEX(Sheet4!A:A, ROW()-COUNTA(Sheet1!A:A)))} -> Al0.2CoCrFeNi | B758: =_xlfn.XLOOKUP(A758, Sheet4!A:A, Sheet4!C:C) -> BCC1+B2(ordered BCC) | C758: 1 | D758: =_xlfn.XLOOKUP(A758, Sheet2!A:A, Sheet2!B:B) -> 8 | E758: =_xlfn.XLOOKUP(A758, Sheet1!A:A, Sheet1!G:G) -> -1 | F758: =IF(OR(C758=1, E758=1), 1, IF(OR(C758=0, E758=0), 0, -1)) -> 1 | G758: {=_xlfn.XLOOKUP(A758, Sheet1!A:A, Sheet1!C:F)} -> 23.809524 | H758: 23.809524 | I758: 23.809524 | J758: 23.809524
A759: {=IF(ROW()<=COUNTA(Sheet1!A:A), INDEX(Sheet1!A:A, ROW()), INDEX(Sheet4!A:A, ROW()-COUNTA(Sheet1!A:A)))} -> Al0.2CoFeNiCr0.8 | B759: =_xlfn.XLOOKUP(A759, Sheet4!A:A, Sheet4!C:C) -> 0 | C759: -1 | D759: =_xlfn.XLOOKUP(A759, Sheet2!A:A, Sheet2!B:B) -> 8.1 | E759: =_xlfn.XLOOKUP(A759, Sheet1!A:A, Sheet1!G:G) -> -1 | F759: =IF(OR(C759=1, E759=1), 1, IF(OR(C759=0, E759=0), 0, -1)) -> -1 | G759: {=_xlfn.XLOOKUP(A759, Sheet1!A:A, Sheet1!C:F)} -> 25 | H759: 20 | I759: 25 | J759: 25
A760: {=IF(ROW()<=COUNTA(Sheet1!A:A), INDEX(Sheet1!A:A, ROW()), INDEX(Sheet4!A:A, ROW()-COUNTA(Sheet1!A:A)))} -> Al0.3CoCr2FeNi | B760: =_xlfn.XLOOKUP(A760, Sheet4!A:A, Sheet4!C:C) -> 0 | C760: -1 | D760: =_xlfn.XLOOKUP(A760, Sheet2!A:A, Sheet2!B:B) -> 7.5283 | E760: =_xlfn.XLOOKUP(A760, Sheet1!A:A, Sheet1!G:G) -> -1 | F760: =IF(OR(C760=1, E760=1), 1, IF(OR(C760=0, E760=0), 0, -1)) -> -1 | G760: {=_xlfn.XLOOKUP(A760, Sheet1!A:A, Sheet1!C:F)} -> 18.867925 | H760: 37.735849 | I760: 18.867925 | J760: 18.867925
A761: {=IF(ROW()<=COUNTA(Sheet1!A:A), INDEX(Sheet1!A:A, ROW()), INDEX(Sheet4!A:A, ROW()-COUNTA(Sheet1!A:A)))} -> Al0.25CoCrFeNi | B761: =_xlfn.XLOOKUP(A761, Sheet4!A:A, Sheet4!C:C) -> FCC | C761: 0 | D761: =_xlfn.XLOOKUP(A761, Sheet2!A:A, Sheet2!B:B) -> 7.9412 | E761: =_xlfn.XLOOKUP(A761, Sheet1!A:A, Sheet1!G:G) -> -1 | F761: =IF(OR(C761=1, E761=1), 1, IF(OR(C761=0, E761=0), 0, -1)) -> 0 | G761: {=_xlfn.XLOOKUP(A761, Sheet1!A:A, Sheet1!C:F)} -> 23.529412 | H761: 23.529412 | I761: 23.529412 | J761: 23.529412
A762: {=IF(ROW()<=COUNTA(Sheet1!A:A), INDEX(Sheet1!A:A, ROW()), INDEX(Sheet4!A:A, ROW()-COUNTA(Sheet1!A:A)))} -> Al0.25CoCrFeNi | B762: =_xlfn.XLOOKUP(A762, Sheet4!A:A, Sheet4!C:C) -> FCC | C762: 0 | D762: =_xlfn.XLOOKUP(A762, Sheet2!A:A, Sheet2!B:B) -> 7.9412 | E762: =_xlfn.XLOOKUP(A762, Sheet1!A:A, Sheet1!G:G) -> -1 | F762: =IF(OR(C762=1, E762=1), 1, IF(OR(C762=0, E762=0), 0, -1)) -> 0 | G762: {=_xlfn.XLOOKUP(A762, Sheet1!A:A, Sheet1!C:F)} -> 23.529412 | H762: 23.529412 | I762: 23.529412 | J762: 23.529412
A763: {=IF(ROW()<=COUNTA(Sheet1!A:A), INDEX(Sheet1!A:A, ROW()), INDEX(Sheet4!A:A, ROW()-COUNTA(Sheet1!A:A)))} -> Al0.3CoCrFeNi | B763: =_xlfn.XLOOKUP(A763, Sheet4!A:A, Sheet4!C:C) -> IM | C763: -1 | D763: =_xlfn.XLOOKUP(A763, Sheet2!A:A, Sheet2!B:B) -> 7.8837 | E763: =_xlfn.XLOOKUP(A763, Sheet1!A:A, Sheet1!G:G) -> -1 | F763: =IF(OR(C763=1, E763=1), 1, IF(OR(C763=0, E763=0), 0, -1)) -> -1 | G763: {=_xlfn.XLOOKUP(A763, Sheet1!A:A, Sheet1!C:F)} -> 23.529412 | H763: 23.529412 | I763: 23.529412 | J763: 23.529412
... A1422: {=IF(ROW()<=COUNTA(Sheet1!A:A), INDEX(Sheet1!A:A, ROW()), INDEX(Sheet4!A:A, ROW()-COUNTA(Sheet1!A:A)))} -> Al47.5Cr14.5Fe18.9Co8.3Ni10.7 | B1422: =_xlfn.XLOOKUP(A1422, Sheet4!A:A, Sheet4!C:C) -> 0 | C1422: -1 | D1422: =_xlfn.XLOOKUP(A1422, Sheet2!A:A, Sheet2!B:B) -> 5.6296 | E1422: =_xlfn.XLOOKUP(A1422, Sheet1!A:A, Sheet1!G:G) -> -1 | F1422: =IF(OR(C1422=1, E1422=1), 1, IF(OR(C1422=0, E1422=0), 0, -1)) -> -1 | G1422: {=_xlfn.XLOOKUP(A1422, Sheet1!A:A, Sheet1!C:F)} -> 8.9 | H1422: 15.3 | I1422: 20.2 | J1422: 11.5
